{
 "cells": [
  {
   "cell_type": "code",
   "execution_count": 1,
   "id": "1d73106b",
   "metadata": {},
   "outputs": [],
   "source": [
    "import os\n",
    "import cv2 as cv\n",
    "import numpy as np"
   ]
  },
  {
   "cell_type": "code",
   "execution_count": 2,
   "id": "5ceae9bb",
   "metadata": {},
   "outputs": [
    {
     "name": "stdout",
     "output_type": "stream",
     "text": [
      "['lionel_messi', 'maria_sharapova', 'roger_federer', 'serena_williams', 'virat_kohli']\n"
     ]
    }
   ],
   "source": [
    "p = []\n",
    "for i in os.listdir('Dataset'):\n",
    "    p.append(i)\n",
    "print(p)"
   ]
  },
  {
   "cell_type": "code",
   "execution_count": 3,
   "id": "3d0ef1f2",
   "metadata": {},
   "outputs": [],
   "source": [
    "people = ['lionel_messi', 'maria_sharapova', 'roger_federer', 'serena_williams', 'virat_kohli']\n",
    "DIR = r'C:\\Users\\khatr\\Downloads\\jupitor_notebook\\Deep_Learning\\Open-cv\\3-Faces\\Dataset'"
   ]
  },
  {
   "cell_type": "code",
   "execution_count": 4,
   "id": "9d97aa3a",
   "metadata": {},
   "outputs": [],
   "source": [
    "haar_cascade = cv.CascadeClassifier('haar_face.xml')"
   ]
  },
  {
   "cell_type": "code",
   "execution_count": 5,
   "id": "a3d1175e",
   "metadata": {},
   "outputs": [
    {
     "name": "stdout",
     "output_type": "stream",
     "text": [
      "Training done ---------------\n"
     ]
    }
   ],
   "source": [
    "features = []\n",
    "labels = []\n",
    "\n",
    "def create_train():\n",
    "    for person in people:\n",
    "        path = os.path.join(DIR, person)\n",
    "        label = people.index(person)\n",
    "        \n",
    "        for img in os.listdir(path):\n",
    "            img_path = os.path.join(path, img)\n",
    "            \n",
    "            img_array = cv.imread(img_path)\n",
    "            if img_array is None:\n",
    "                continue\n",
    "            gray = cv.cvtColor(img_array, cv.COLOR_BGR2GRAY)\n",
    "            \n",
    "            faces_rect = haar_cascade.detectMultiScale(gray, scaleFactor = 1.1, minNeighbors = 4)\n",
    "            \n",
    "            for (x,y,w,h) in faces_rect:\n",
    "                faces_roi = gray[y:y+h, x:x+w]\n",
    "                features.append(faces_roi)\n",
    "                labels.append(label)\n",
    "                \n",
    "create_train()\n",
    "print('Training done ---------------')"
   ]
  },
  {
   "cell_type": "code",
   "execution_count": 6,
   "id": "5cfe0edc",
   "metadata": {},
   "outputs": [
    {
     "name": "stdout",
     "output_type": "stream",
     "text": [
      "769\n",
      "769\n"
     ]
    }
   ],
   "source": [
    "print(len(features))\n",
    "print(len(labels))"
   ]
  },
  {
   "cell_type": "code",
   "execution_count": 11,
   "id": "f63cf4d0",
   "metadata": {},
   "outputs": [
    {
     "name": "stdout",
     "output_type": "stream",
     "text": [
      "Collecting opencv-contrib-python\n",
      "  Downloading opencv_contrib_python-4.5.5.64-cp36-abi3-win_amd64.whl (42.2 MB)\n",
      "Note: you may need to restart the kernel to use updated packages.\n"
     ]
    },
    {
     "name": "stderr",
     "output_type": "stream",
     "text": [
      "ERROR: Exception:\n",
      "Traceback (most recent call last):\n",
      "  File \"C:\\Users\\khatr\\anaconda3\\lib\\site-packages\\pip\\_vendor\\resolvelib\\resolvers.py\", line 171, in _merge_into_criterion\n",
      "    crit = self.state.criteria[name]\n",
      "KeyError: 'opencv-contrib-python'\n",
      "\n",
      "During handling of the above exception, another exception occurred:\n",
      "\n",
      "Traceback (most recent call last):\n",
      "  File \"C:\\Users\\khatr\\anaconda3\\lib\\site-packages\\pip\\_vendor\\urllib3\\response.py\", line 438, in _error_catcher\n",
      "    yield\n",
      "  File \"C:\\Users\\khatr\\anaconda3\\lib\\site-packages\\pip\\_vendor\\urllib3\\response.py\", line 519, in read\n",
      "    data = self._fp.read(amt) if not fp_closed else b\"\"\n",
      "  File \"C:\\Users\\khatr\\anaconda3\\lib\\site-packages\\pip\\_vendor\\cachecontrol\\filewrapper.py\", line 62, in read\n",
      "    data = self.__fp.read(amt)\n",
      "  File \"C:\\Users\\khatr\\anaconda3\\lib\\http\\client.py\", line 458, in read\n",
      "    n = self.readinto(b)\n",
      "  File \"C:\\Users\\khatr\\anaconda3\\lib\\http\\client.py\", line 502, in readinto\n",
      "    n = self.fp.readinto(b)\n",
      "  File \"C:\\Users\\khatr\\anaconda3\\lib\\socket.py\", line 669, in readinto\n",
      "    return self._sock.recv_into(b)\n",
      "  File \"C:\\Users\\khatr\\anaconda3\\lib\\ssl.py\", line 1241, in recv_into\n",
      "    return self.read(nbytes, buffer)\n",
      "  File \"C:\\Users\\khatr\\anaconda3\\lib\\ssl.py\", line 1099, in read\n",
      "    return self._sslobj.read(len, buffer)\n",
      "socket.timeout: The read operation timed out\n",
      "\n",
      "During handling of the above exception, another exception occurred:\n",
      "\n",
      "Traceback (most recent call last):\n",
      "  File \"C:\\Users\\khatr\\anaconda3\\lib\\site-packages\\pip\\_internal\\cli\\base_command.py\", line 189, in _main\n",
      "    status = self.run(options, args)\n",
      "  File \"C:\\Users\\khatr\\anaconda3\\lib\\site-packages\\pip\\_internal\\cli\\req_command.py\", line 178, in wrapper\n",
      "    return func(self, options, args)\n",
      "  File \"C:\\Users\\khatr\\anaconda3\\lib\\site-packages\\pip\\_internal\\commands\\install.py\", line 316, in run\n",
      "    requirement_set = resolver.resolve(\n",
      "  File \"C:\\Users\\khatr\\anaconda3\\lib\\site-packages\\pip\\_internal\\resolution\\resolvelib\\resolver.py\", line 121, in resolve\n",
      "    self._result = resolver.resolve(\n",
      "  File \"C:\\Users\\khatr\\anaconda3\\lib\\site-packages\\pip\\_vendor\\resolvelib\\resolvers.py\", line 453, in resolve\n",
      "    state = resolution.resolve(requirements, max_rounds=max_rounds)\n",
      "  File \"C:\\Users\\khatr\\anaconda3\\lib\\site-packages\\pip\\_vendor\\resolvelib\\resolvers.py\", line 318, in resolve\n",
      "    name, crit = self._merge_into_criterion(r, parent=None)\n",
      "  File \"C:\\Users\\khatr\\anaconda3\\lib\\site-packages\\pip\\_vendor\\resolvelib\\resolvers.py\", line 173, in _merge_into_criterion\n",
      "    crit = Criterion.from_requirement(self._p, requirement, parent)\n",
      "  File \"C:\\Users\\khatr\\anaconda3\\lib\\site-packages\\pip\\_vendor\\resolvelib\\resolvers.py\", line 82, in from_requirement\n",
      "    if not cands:\n",
      "  File \"C:\\Users\\khatr\\anaconda3\\lib\\site-packages\\pip\\_vendor\\resolvelib\\structs.py\", line 124, in __bool__\n",
      "    return bool(self._sequence)\n",
      "  File \"C:\\Users\\khatr\\anaconda3\\lib\\site-packages\\pip\\_internal\\resolution\\resolvelib\\found_candidates.py\", line 143, in __bool__\n",
      "    return any(self)\n",
      "  File \"C:\\Users\\khatr\\anaconda3\\lib\\site-packages\\pip\\_internal\\resolution\\resolvelib\\found_candidates.py\", line 38, in _iter_built\n",
      "    candidate = func()\n",
      "  File \"C:\\Users\\khatr\\anaconda3\\lib\\site-packages\\pip\\_internal\\resolution\\resolvelib\\factory.py\", line 167, in _make_candidate_from_link\n",
      "    self._link_candidate_cache[link] = LinkCandidate(\n",
      "  File \"C:\\Users\\khatr\\anaconda3\\lib\\site-packages\\pip\\_internal\\resolution\\resolvelib\\candidates.py\", line 300, in __init__\n",
      "    super().__init__(\n",
      "  File \"C:\\Users\\khatr\\anaconda3\\lib\\site-packages\\pip\\_internal\\resolution\\resolvelib\\candidates.py\", line 144, in __init__\n",
      "    self.dist = self._prepare()\n",
      "  File \"C:\\Users\\khatr\\anaconda3\\lib\\site-packages\\pip\\_internal\\resolution\\resolvelib\\candidates.py\", line 226, in _prepare\n",
      "    dist = self._prepare_distribution()\n",
      "  File \"C:\\Users\\khatr\\anaconda3\\lib\\site-packages\\pip\\_internal\\resolution\\resolvelib\\candidates.py\", line 311, in _prepare_distribution\n",
      "    return self._factory.preparer.prepare_linked_requirement(\n",
      "  File \"C:\\Users\\khatr\\anaconda3\\lib\\site-packages\\pip\\_internal\\operations\\prepare.py\", line 457, in prepare_linked_requirement\n",
      "    return self._prepare_linked_requirement(req, parallel_builds)\n",
      "  File \"C:\\Users\\khatr\\anaconda3\\lib\\site-packages\\pip\\_internal\\operations\\prepare.py\", line 480, in _prepare_linked_requirement\n",
      "    local_file = unpack_url(\n",
      "  File \"C:\\Users\\khatr\\anaconda3\\lib\\site-packages\\pip\\_internal\\operations\\prepare.py\", line 230, in unpack_url\n",
      "    file = get_http_url(\n",
      "  File \"C:\\Users\\khatr\\anaconda3\\lib\\site-packages\\pip\\_internal\\operations\\prepare.py\", line 108, in get_http_url\n",
      "    from_path, content_type = download(link, temp_dir.path)\n",
      "  File \"C:\\Users\\khatr\\anaconda3\\lib\\site-packages\\pip\\_internal\\network\\download.py\", line 163, in __call__\n",
      "    for chunk in chunks:\n",
      "  File \"C:\\Users\\khatr\\anaconda3\\lib\\site-packages\\pip\\_internal\\cli\\progress_bars.py\", line 159, in iter\n",
      "    for x in it:\n",
      "  File \"C:\\Users\\khatr\\anaconda3\\lib\\site-packages\\pip\\_internal\\network\\utils.py\", line 64, in response_chunks\n",
      "    for chunk in response.raw.stream(\n",
      "  File \"C:\\Users\\khatr\\anaconda3\\lib\\site-packages\\pip\\_vendor\\urllib3\\response.py\", line 576, in stream\n",
      "    data = self.read(amt=amt, decode_content=decode_content)\n",
      "  File \"C:\\Users\\khatr\\anaconda3\\lib\\site-packages\\pip\\_vendor\\urllib3\\response.py\", line 541, in read\n",
      "    raise IncompleteRead(self._fp_bytes_read, self.length_remaining)\n",
      "  File \"C:\\Users\\khatr\\anaconda3\\lib\\contextlib.py\", line 131, in __exit__\n",
      "    self.gen.throw(type, value, traceback)\n",
      "  File \"C:\\Users\\khatr\\anaconda3\\lib\\site-packages\\pip\\_vendor\\urllib3\\response.py\", line 443, in _error_catcher\n",
      "    raise ReadTimeoutError(self._pool, None, \"Read timed out.\")\n",
      "pip._vendor.urllib3.exceptions.ReadTimeoutError: HTTPSConnectionPool(host='files.pythonhosted.org', port=443): Read timed out.\n"
     ]
    }
   ],
   "source": [
    "pip install opencv-contrib-python"
   ]
  },
  {
   "cell_type": "code",
   "execution_count": 9,
   "id": "8b0645a5",
   "metadata": {},
   "outputs": [
    {
     "name": "stdout",
     "output_type": "stream",
     "text": [
      "Collecting opencv-contrib-python\n",
      "  Downloading opencv_contrib_python-4.5.5.64-cp36-abi3-win_amd64.whl (42.2 MB)\n",
      "Note: you may need to restart the kernel to use updated packages.\n"
     ]
    },
    {
     "name": "stderr",
     "output_type": "stream",
     "text": [
      "ERROR: Exception:\n",
      "Traceback (most recent call last):\n",
      "  File \"C:\\Users\\khatr\\anaconda3\\lib\\site-packages\\pip\\_vendor\\resolvelib\\resolvers.py\", line 171, in _merge_into_criterion\n",
      "    crit = self.state.criteria[name]\n",
      "KeyError: 'opencv-contrib-python'\n",
      "\n",
      "During handling of the above exception, another exception occurred:\n",
      "\n",
      "Traceback (most recent call last):\n",
      "  File \"C:\\Users\\khatr\\anaconda3\\lib\\site-packages\\pip\\_vendor\\urllib3\\response.py\", line 438, in _error_catcher\n",
      "    yield\n",
      "  File \"C:\\Users\\khatr\\anaconda3\\lib\\site-packages\\pip\\_vendor\\urllib3\\response.py\", line 519, in read\n",
      "    data = self._fp.read(amt) if not fp_closed else b\"\"\n",
      "  File \"C:\\Users\\khatr\\anaconda3\\lib\\site-packages\\pip\\_vendor\\cachecontrol\\filewrapper.py\", line 62, in read\n",
      "    data = self.__fp.read(amt)\n",
      "  File \"C:\\Users\\khatr\\anaconda3\\lib\\http\\client.py\", line 458, in read\n",
      "    n = self.readinto(b)\n",
      "  File \"C:\\Users\\khatr\\anaconda3\\lib\\http\\client.py\", line 502, in readinto\n",
      "    n = self.fp.readinto(b)\n",
      "  File \"C:\\Users\\khatr\\anaconda3\\lib\\socket.py\", line 669, in readinto\n",
      "    return self._sock.recv_into(b)\n",
      "  File \"C:\\Users\\khatr\\anaconda3\\lib\\ssl.py\", line 1241, in recv_into\n",
      "    return self.read(nbytes, buffer)\n",
      "  File \"C:\\Users\\khatr\\anaconda3\\lib\\ssl.py\", line 1099, in read\n",
      "    return self._sslobj.read(len, buffer)\n",
      "socket.timeout: The read operation timed out\n",
      "\n",
      "During handling of the above exception, another exception occurred:\n",
      "\n",
      "Traceback (most recent call last):\n",
      "  File \"C:\\Users\\khatr\\anaconda3\\lib\\site-packages\\pip\\_internal\\cli\\base_command.py\", line 189, in _main\n",
      "    status = self.run(options, args)\n",
      "  File \"C:\\Users\\khatr\\anaconda3\\lib\\site-packages\\pip\\_internal\\cli\\req_command.py\", line 178, in wrapper\n",
      "    return func(self, options, args)\n",
      "  File \"C:\\Users\\khatr\\anaconda3\\lib\\site-packages\\pip\\_internal\\commands\\install.py\", line 316, in run\n",
      "    requirement_set = resolver.resolve(\n",
      "  File \"C:\\Users\\khatr\\anaconda3\\lib\\site-packages\\pip\\_internal\\resolution\\resolvelib\\resolver.py\", line 121, in resolve\n",
      "    self._result = resolver.resolve(\n",
      "  File \"C:\\Users\\khatr\\anaconda3\\lib\\site-packages\\pip\\_vendor\\resolvelib\\resolvers.py\", line 453, in resolve\n",
      "    state = resolution.resolve(requirements, max_rounds=max_rounds)\n",
      "  File \"C:\\Users\\khatr\\anaconda3\\lib\\site-packages\\pip\\_vendor\\resolvelib\\resolvers.py\", line 318, in resolve\n",
      "    name, crit = self._merge_into_criterion(r, parent=None)\n",
      "  File \"C:\\Users\\khatr\\anaconda3\\lib\\site-packages\\pip\\_vendor\\resolvelib\\resolvers.py\", line 173, in _merge_into_criterion\n",
      "    crit = Criterion.from_requirement(self._p, requirement, parent)\n",
      "  File \"C:\\Users\\khatr\\anaconda3\\lib\\site-packages\\pip\\_vendor\\resolvelib\\resolvers.py\", line 82, in from_requirement\n",
      "    if not cands:\n",
      "  File \"C:\\Users\\khatr\\anaconda3\\lib\\site-packages\\pip\\_vendor\\resolvelib\\structs.py\", line 124, in __bool__\n",
      "    return bool(self._sequence)\n",
      "  File \"C:\\Users\\khatr\\anaconda3\\lib\\site-packages\\pip\\_internal\\resolution\\resolvelib\\found_candidates.py\", line 143, in __bool__\n",
      "    return any(self)\n",
      "  File \"C:\\Users\\khatr\\anaconda3\\lib\\site-packages\\pip\\_internal\\resolution\\resolvelib\\found_candidates.py\", line 38, in _iter_built\n",
      "    candidate = func()\n",
      "  File \"C:\\Users\\khatr\\anaconda3\\lib\\site-packages\\pip\\_internal\\resolution\\resolvelib\\factory.py\", line 167, in _make_candidate_from_link\n",
      "    self._link_candidate_cache[link] = LinkCandidate(\n",
      "  File \"C:\\Users\\khatr\\anaconda3\\lib\\site-packages\\pip\\_internal\\resolution\\resolvelib\\candidates.py\", line 300, in __init__\n",
      "    super().__init__(\n",
      "  File \"C:\\Users\\khatr\\anaconda3\\lib\\site-packages\\pip\\_internal\\resolution\\resolvelib\\candidates.py\", line 144, in __init__\n",
      "    self.dist = self._prepare()\n",
      "  File \"C:\\Users\\khatr\\anaconda3\\lib\\site-packages\\pip\\_internal\\resolution\\resolvelib\\candidates.py\", line 226, in _prepare\n",
      "    dist = self._prepare_distribution()\n",
      "  File \"C:\\Users\\khatr\\anaconda3\\lib\\site-packages\\pip\\_internal\\resolution\\resolvelib\\candidates.py\", line 311, in _prepare_distribution\n",
      "    return self._factory.preparer.prepare_linked_requirement(\n",
      "  File \"C:\\Users\\khatr\\anaconda3\\lib\\site-packages\\pip\\_internal\\operations\\prepare.py\", line 457, in prepare_linked_requirement\n",
      "    return self._prepare_linked_requirement(req, parallel_builds)\n",
      "  File \"C:\\Users\\khatr\\anaconda3\\lib\\site-packages\\pip\\_internal\\operations\\prepare.py\", line 480, in _prepare_linked_requirement\n",
      "    local_file = unpack_url(\n",
      "  File \"C:\\Users\\khatr\\anaconda3\\lib\\site-packages\\pip\\_internal\\operations\\prepare.py\", line 230, in unpack_url\n",
      "    file = get_http_url(\n",
      "  File \"C:\\Users\\khatr\\anaconda3\\lib\\site-packages\\pip\\_internal\\operations\\prepare.py\", line 108, in get_http_url\n",
      "    from_path, content_type = download(link, temp_dir.path)\n",
      "  File \"C:\\Users\\khatr\\anaconda3\\lib\\site-packages\\pip\\_internal\\network\\download.py\", line 163, in __call__\n",
      "    for chunk in chunks:\n",
      "  File \"C:\\Users\\khatr\\anaconda3\\lib\\site-packages\\pip\\_internal\\cli\\progress_bars.py\", line 159, in iter\n",
      "    for x in it:\n",
      "  File \"C:\\Users\\khatr\\anaconda3\\lib\\site-packages\\pip\\_internal\\network\\utils.py\", line 64, in response_chunks\n",
      "    for chunk in response.raw.stream(\n",
      "  File \"C:\\Users\\khatr\\anaconda3\\lib\\site-packages\\pip\\_vendor\\urllib3\\response.py\", line 576, in stream\n",
      "    data = self.read(amt=amt, decode_content=decode_content)\n",
      "  File \"C:\\Users\\khatr\\anaconda3\\lib\\site-packages\\pip\\_vendor\\urllib3\\response.py\", line 541, in read\n",
      "    raise IncompleteRead(self._fp_bytes_read, self.length_remaining)\n",
      "  File \"C:\\Users\\khatr\\anaconda3\\lib\\contextlib.py\", line 131, in __exit__\n",
      "    self.gen.throw(type, value, traceback)\n",
      "  File \"C:\\Users\\khatr\\anaconda3\\lib\\site-packages\\pip\\_vendor\\urllib3\\response.py\", line 443, in _error_catcher\n",
      "    raise ReadTimeoutError(self._pool, None, \"Read timed out.\")\n",
      "pip._vendor.urllib3.exceptions.ReadTimeoutError: HTTPSConnectionPool(host='files.pythonhosted.org', port=443): Read timed out.\n"
     ]
    }
   ],
   "source": [
    "pip install --user opencv-contrib-python"
   ]
  },
  {
   "cell_type": "code",
   "execution_count": 8,
   "id": "810307aa",
   "metadata": {},
   "outputs": [
    {
     "ename": "AttributeError",
     "evalue": "module 'cv2.cv2' has no attribute 'face'",
     "output_type": "error",
     "traceback": [
      "\u001b[1;31m---------------------------------------------------------------------------\u001b[0m",
      "\u001b[1;31mAttributeError\u001b[0m                            Traceback (most recent call last)",
      "\u001b[1;32m<ipython-input-8-91751f407198>\u001b[0m in \u001b[0;36m<module>\u001b[1;34m\u001b[0m\n\u001b[0;32m      2\u001b[0m \u001b[0mlabels\u001b[0m \u001b[1;33m=\u001b[0m \u001b[0mnp\u001b[0m\u001b[1;33m.\u001b[0m\u001b[0marray\u001b[0m\u001b[1;33m(\u001b[0m\u001b[0mlabels\u001b[0m\u001b[1;33m)\u001b[0m\u001b[1;33m\u001b[0m\u001b[1;33m\u001b[0m\u001b[0m\n\u001b[0;32m      3\u001b[0m \u001b[1;33m\u001b[0m\u001b[0m\n\u001b[1;32m----> 4\u001b[1;33m \u001b[0mface_recognizer\u001b[0m \u001b[1;33m=\u001b[0m \u001b[0mcv\u001b[0m\u001b[1;33m.\u001b[0m\u001b[0mface\u001b[0m\u001b[1;33m.\u001b[0m\u001b[0mLBPHFaceRecognizer_create\u001b[0m\u001b[1;33m(\u001b[0m\u001b[1;33m)\u001b[0m\u001b[1;33m\u001b[0m\u001b[1;33m\u001b[0m\u001b[0m\n\u001b[0m\u001b[0;32m      5\u001b[0m \u001b[1;33m\u001b[0m\u001b[0m\n\u001b[0;32m      6\u001b[0m \u001b[1;31m# Train the Recognizer on the features list and the labels list\u001b[0m\u001b[1;33m\u001b[0m\u001b[1;33m\u001b[0m\u001b[1;33m\u001b[0m\u001b[0m\n",
      "\u001b[1;31mAttributeError\u001b[0m: module 'cv2.cv2' has no attribute 'face'"
     ]
    }
   ],
   "source": [
    "features = np.array(features, dtype='object')\n",
    "labels = np.array(labels) \n",
    "\n",
    "face_recognizer = cv.face.LBPHFaceRecognizer_create()\n",
    "\n",
    "# Train the Recognizer on the features list and the labels list\n",
    "face_recognizer.train(features,labels)\n",
    "\n",
    "face_recognizer.save('face_trained.yml')\n",
    "np.save('features.npy', features)\n",
    "np.save('labels.npy', labels)"
   ]
  },
  {
   "cell_type": "code",
   "execution_count": null,
   "id": "19fd5598",
   "metadata": {},
   "outputs": [],
   "source": [
    "\n"
   ]
  },
  {
   "cell_type": "code",
   "execution_count": null,
   "id": "19a15b6f",
   "metadata": {},
   "outputs": [],
   "source": []
  }
 ],
 "metadata": {
  "kernelspec": {
   "display_name": "Python 3",
   "language": "python",
   "name": "python3"
  },
  "language_info": {
   "codemirror_mode": {
    "name": "ipython",
    "version": 3
   },
   "file_extension": ".py",
   "mimetype": "text/x-python",
   "name": "python",
   "nbconvert_exporter": "python",
   "pygments_lexer": "ipython3",
   "version": "3.8.8"
  }
 },
 "nbformat": 4,
 "nbformat_minor": 5
}
